Workbook

Sheet Instruçoes
A1: FIAP | B1: Modelo Financeiro para Novos Negócios ( Startup One ou Discovery)
A2: Intruções de Preenchimento
A3: 1. Geral
A4: 45658 | B4: Preencha somente os campos em amarelo das abas : "Premissa de Receitas", "Premissade Despesas, "Premissas de Investimento
A5: 45689 | B5: A aba "Folha de Pagamento" é apenas um valor referencial, para que depois você coloque o valor na aba "premissas e Despesas
A6: 45717 | B6: As abas "Projeção Financeira" e "Resumo"" são automatizads, ou seja, não precisam ser preenchidas
A7: 2. Premissa Receitas (O quanto o seu negócio gera de receita)
A8: 45659 | B8: Preencha o TAM/SAM/SOM estudado, em volume financeiro de faturamento de mercado
A9: 45690 | B9: Selecione o tipo de atividade na qual seu negócio atuará , o que definirá o cálculo de imposto
A10: 45718 | B10: Em seguida, preencha média aproximada de preço (ticket médio), para calcularmos a projeção de clientes. Defina também o perrcentual de cliente que deseja alcançar no primeiro ano e no primeiro mês, assim como a taxa % de cfrescimento mensal.
A11: 45749 | B11: Em seguida, preencha o modelo de Monetização. Você pode escolher mais de um. Nesta hora você deve percentiualizar qual a representatividade de cada modelo ( Ex. 70% Assinatura/ 30% B2B) e definir preço de venda e custo dos serviços/produtos, assim como percentual de vendas de cada um deles em cada bloco de monetização
A12: 3. Premissa Despesas ( o quanto o seu negócio gera de custos)
A13: 45660 | B13: Preencha os grupos de despesas , considerando uma somatoria de valores que gastaria mensalmente
A14: 45691 | B14: Para cada grupo de despesas, considere valhores de folha de pagamento mensal existente naquele grupo
A15: 45719 | B15: Defina a estimativa anual de reajustes de despesas , que ocorre natuaralmente todo ano
A16: 4. Premissa investimento Inicial ( o quanto você precisa para começar seu negócio, seja com investimentos próprios ou com captaçoes de mercdo)
A17: 45661 | B17: Preencha os grupos deinvestimento , considerando uma somatoria de valores que precisaria para começar este negócio

Sheet 1.Premissas Receitas
A1: Suposições de receita
A3: Tamanho de Mercado (Trazer números em valor financeiro de faturamento do setor escolhido)
A4: Tam | B4: Somatória das receitas geradas por todos os players do seu segmento. | E4: 91500000000
A5: Sam | B5: Somatória das receitas que você poderia ganhar vendendo o seu produto em um segmento. | E5: 20500000000
A6: Som | B6: Quantos $$$ destes realmente você vai conseguir considerando concorrentes, região, tendências, demanda esperada | E6: 134400000
A8: Atividade: | B8: 2 | C8: 2 | D8: 2
A9: 1 para Comércio
A10: 2 para Serviços
A11: 3 para Indústria
A14: Projeção de Clientes | B14: % SOM | C14: Total
A15: Preço Médio | B15: 96000 | F15: Crescimento Anual
A16: Numero de clientes em 5 anos | B16: =E6/B15 -> 1400 | C16: =B16 -> 1400 | F16: % Cresc. Ano 2 | G16: 0.4
A17: Numero de cliente no Primeiro ano | B17: 0.05 | C17: =B17*C16 -> 70 | F17: % Cresc. Ano 3 | G17: 0.3
A18: Número de Cliente no Primeiro Mês | B18: 0.1 | C18: =C17/21 -> 3.3333333 | F18: % Cresc. Ano 4 | G18: 0.2
A19: % Cres Mensal | B19: 0.03 | F19: % Cresc. Ano 5 | G19: 0.15
A22: Modelo de Monetização (Preencha apenas o(s) modelo(s) escolhido(s), que podem ser mais de um)
A24: Assinatura (SaaS) | B24: O que contempla? | C24: $ preço de venda | D24: $ Custo unitário | E24: Margem | F24: % Vendas | G24: Clientes Mês 1
A25: # de clientes Assinatura Fremium | B25: Free trial + estimativas limitadas (self-serve) | C25: 1 | D25: 0 | E25: =1-D25/C25 -> 1 | F25: 0.5 | G25: =F25*$B$29 -> 1
A26: # de clientes Assinatura 1 | B26: SaaS por volume de jobs preditos (ticket medio mensal) | C26: 500 | D26: 150 | E26: =1-D26/C26 -> 0.7 | F26: 0.35 | G26: =F26*$B$29 -> 0.7
A27: # de clientes Assinatura 2 | B27: Assinatura Enterprise por usuario | C27: 1400 | D27: 420 | E27: =1-D27/C27 -> 0.7 | F27: 0.15 | G27: =F27*$B$29 -> 0.3
A28: Perececentual de faturamento do Modelo | B28: 0.6
A29: Clientes no primeiro mês | B29: =$C$18*B28 -> 2
A30: % Churn - cancelamentos mensais | B30: 0.03
A32: Marketplace | B32: O que contempla? | C32: $ preço médio de venda | D32: $ Custo unitário | E32: Margem | F32: % Vendas | G32: Clientes Mês 1
A33: # de clientes marketplace % Comissão 1 | C33: 1 | D33: 0 | E33: =1-D33/C33 -> 1 | F33: 0 | G33: =F33*$B$37 -> 0
A34: # de clientes marketplace % Comissão 2 | C34: 1 | D34: 0 | E34: =1-D34/C34 -> 1 | G34: =F34*$B$37 -> 0
A35: # de clientes marketplace % Comissão 3 | C35: 1 | D35: 0 | E35: =1-D35/C35 -> 1 | G35: =F35*$B$37 -> 0
A36: Perececentual de faturamento do Modelo | B36: 0
A37: Clientes no primeiro mês | B37: =$C$18*B36 -> 0
A39: B2B | B39: O que contempla? | C39: $ preço de venda | D39: $ Custo unitário | E39: Margem | F39: % Vendas | G39: Clientes Mês 1
A40: # de clientes B2B Setup | B40: Setup + integracao (Dagster/Spark, onboarding) | C40: 15000 | D40: 5000 | E40: =1-D40/C40 -> 0.66666667 | F40: 1 | G40: =F40*$B$44 -> 1.3333333
A41: # de clientes B2B Mensalidade | B41: Success Fee medio mensal (8-12% do saving gerado) | C41: 8000 | D41: 800 | E41: =1-D41/C41 -> 0.9 | F41: 1 | G41: =F41*$B$44 -> 1.3333333
A42: # de clientes B2B Manutenção | C42: 1 | D42: 0 | E42: =1-D42/C42 -> 1 | F42: 0 | G42: =F42*$B$44 -> 0
A43: Perececentual de faturamento do Modelo | B43: 0.4
A44: Clientes no primeiro mês | B44: =$C$18*B43 -> 1.3333333
A47: Conteúdo Premium/Paywall | B47: O que contempla? | C47: $ preço de venda | D47: $ Custo unitário | E47: Margem | F47: % Vendas | G47: Clientes Mês 1
A48: # de clientes Conteudo/ Paywall 1 | C48: 1 | D48: 0 | E48: =1-D48/C48 -> 1 | F48: 0 | G48: =F48*$B$52 -> 0
A49: # de clientes Conteudo/ Paywall 2 | C49: 1 | D49: 0 | E49: =1-D49/C49 -> 1 | G49: =F49*$B$52 -> 0
A50: # de clientes Conteudo/ Paywall 3 | C50: 1 | D50: 0 | E50: =1-D50/C50 -> 1 | G50: =F50*$B$52 -> 0
A51: Perececentual de faturamento do Modelo | B51: 0
...

Sheet 2.Folha de Pagamentos
A1: Folha de Pagamentos ( Valores ilustrativos)
A4: # | B4: Name | C4: Título | D4: Departamento | E4: Começo | F4: Final | G4: Salário Anual | H4: Aumento Anual | I4: Impostos
A6: 1 | B6: Fundador(a) 1 | C6: CEO | D6: G&A | E6: 46266 | F6: 73050 | G6: 180000 | H6: 0.05 | I6: 0.15
A7: =+A6+1 -> 2 | B7: Fundador(a) 2 | C7: CTO | D7: P&D | E7: 46266 | F7: 73050 | G7: 180000 | H7: 0.05 | I7: 0.15
A8: =+A7+1 -> 3 | B8: Eng. de Dados Senior | C8: Data Engineer Senior | D8: P&D | E8: 46296 | F8: 73050 | G8: 150000 | H8: 0.05 | I8: 0.15
A9: =+A8+1 -> 4 | B9: Eng. de Dados Pleno | C9: Data Engineer Pleno | D9: P&D | E9: 46388 | F9: 73050 | G9: 120000 | H9: 0.05 | I9: 0.15
A10: =+A9+1 -> 5 | B10: Head de Growth | C10: Head de Growth/Vendas | D10: M&V | E10: 46327 | F10: 73050 | G10: 130000 | H10: 0.05 | I10: 0.15
A11: =+A10+1 -> 6 | B11: Analista de CS | C11: Customer Success / FinOps Liaison | D11: M&V | E11: 46419 | F11: 73050 | G11: 90000 | H11: 0.05 | I11: 0.15
A12: =+A11+1 -> 7 | B12: Analista Admin | C12: Controller/Admin (part-time) | D12: G&A | E12: 46266 | F12: 73050 | G12: 60000 | H12: 0.05 | I12: 0.15
A13: =+A12+1 -> 8
A14: =+A13+1 -> 9
A15: =+A14+1 -> 10
A16: =+A15+1 -> 11
A17: =+A16+1 -> 12
A18: =+A17+1 -> 13
A19: =+A18+1 -> 14
A20: =+A19+1 -> 15
A21: =+A20+1 -> 16
A22: =+A21+1 -> 17
A23: =+A22+1 -> 18
A24: =+A23+1 -> 19
... A29: =+A28+1 -> 24

Sheet 3.Premissas de Despesas
A1: Suposições de despesas operacional
A3: Vendas e Marketing | B3: $ Mensal | C3: Ano 1
A4: Serviços de V&M, software, ferramentas, campanhas | B4: 8000 | C4: =B4*12 -> 96000
A5: Folha de pagamento de V&M | B5: 18333 | C5: =B5*12 -> 219996
A7: Pesquisa e Desenvolvimento | B7: $ Mensal | C7: Ano 1
A8: Serviços de P&D, software, ferramentas , custos T&I | B8: 12000 | C8: =B8*12 -> 144000
A9: Folha de pagamento de P&D | B9: 37500 | C9: =B9*12 -> 450000
A11: Geral & Admin | B11: $ Mensal | C11: Ano 1
A12: Aluguel, Energia, Luz e Custos Fixos, internet | B12: 3000 | C12: =B12*12 -> 36000
A13: VIagens e Despesas Extras | B13: 2000 | C13: =B13*12 -> 24000
A14: Serviços de G&A (contabilidade, advogados, consultorias), software, ferramentas - % da Receita | B14: 4000 | C14: =B14*12 -> 48000
A15: Folha de pagamentos de G&A | B15: 20000 | C15: =B15*12 -> 240000
A17: Outras receitas / despesas | C17: Ano 1
A18: Depreciação e Amortização | B18: 1000 | C18: =B18*12 -> 12000
A19: Pró-labore de Sócios | B19: 15000 | C19: =B19*12 -> 180000
A20: Outras despesas | B20: 0 | C20: =B20*12 -> 0
A22: Estimativa de reajustes nas despesas
A23: Ano 02 | B23: 0.1
A24: Ano 03 | B24: 0.15
A25: Ano 04 | B25: 0.2
A26: Ano 05 | B26: 0.25

Sheet 4.Premissas de Investimento
A1: Suposições de Investimentos/ Aporte Iniciais | B1: =B3+B7+B13 -> 170000
A3: Vendas e Marketing | B3: =SUM(B4:B5) -> 25000
A4: Lançamento da solução (Criaçao de Logo e campanha) | B4: 15000
A5: Evento de lançamento | B5: 10000
A7: Pesquisa e Desenvolvimento | B7: =SUM(B8:B11) -> 130000
A8: Contratação de sistemas e ferramentas | B8: 20000
A9: Desenvolvimento da solução | B9: 80000
A10: Equipamentos ( computadores ou devices) | B10: 30000
A11: Estoque inicial ( no caso de devices ou produtos) | B11: 0
A13: Geral & Admin | B13: =SUM(B14:B15) -> 15000
A14: Serviços de G&A (domínios, documentos e taxas de abertura de empresa) | B14: 5000
A15: Gastos Pré-Operacionais | B15: 10000

Sheet 5.Projeção Financeira
A1: Template de Projeção FInanceira
D3: Mês | G3: =+F3+1 -> 1 | H3: =+G3+1 -> 2 | I3: =+H3+1 -> 3 | J3: =+I3+1 -> 4 | K3: =+J3+1 -> 5 | L3: =+K3+1 -> 6 | M3: =+L3+1 -> 7 | N3: =+M3+1 -> 8 | ... BN3: =+BM3+1 -> 60 | BP3: Ano 1 | BQ3: Ano 2 | BR3: Ano 3 | BS3: Ano 4 | BT3: Ano 5
D4: Período | G4: Projeção | H4: Projeção | I4: Projeção | J4: Projeção | K4: Projeção | L4: Projeção | M4: Projeção | N4: Projeção | O4: Projeção | P4: Projeção | Q4: Projeção | R4: Projeção | S4: Projeção | T4: Projeção | U4: Projeção | V4: Projeção | W4: Projeção | X4: Projeção | Y4: Projeção | Z4: Projeção | AA4: Projeção | AB4: Projeção | AC4: Projeção | AD4: Projeção | AE4: Projeção | AF4: Projeção | AG4: Projeção | AH4: Projeção | AI4: Projeção | AJ4: Projeção | AK4: Projeção | AL4: Projeção | AM4: Projeção | AN4: Projeção | AO4: Projeção | AP4: Projeção | AQ4: Projeção | AR4: Projeção | AS4: Projeção | AT4: Projeção | AU4: Projeção | AV4: Projeção | AW4: Projeção | AX4: Projeção | AY4: Projeção | AZ4: Projeção | BA4: Projeção | BB4: Projeção | BC4: Projeção | BD4: Projeção | BE4: Projeção | BF4: Projeção | BG4: Projeção | BH4: Projeção | BI4: Projeção | BJ4: Projeção | BK4: Projeção | BL4: Projeção | BM4: Projeção | BN4: Projeção | BP4: Projeção | BQ4: Projeção | BR4: Projeção | BS4: Projeção | BT4: Projeção
A6: Vendas
B8: Novas vendas
C9: ='1.Premissas Receitas'!A25 -> # de clientes Assinatura Fremium | G9: ='1.Premissas Receitas'!G25 -> 1 | H9: =G9+(G9*'1.Premissas Receitas'!$B$19) -> 1.03 | I9: =H9+(H9*'1.Premissas Receitas'!$B$19) -> 1.0609 | J9: =I9+(I9*'1.Premissas Receitas'!$B$19) -> 1.092727 | K9: =J9+(J9*'1.Premissas Receitas'!$B$19) -> 1.1255088 | L9: =K9+(K9*'1.Premissas Receitas'!$B$19) -> 1.1592741 | M9: =L9+(L9*'1.Premissas Receitas'!$B$19) -> 1.1940523 | N9: =M9+(M9*'1.Premissas Receitas'!$B$19) -> 1.2298739 | O9: =N9+(N9*'1.Premissas Receitas'!$B$19) -> 1.2667701 | ... R9: =Q9+(Q9*'1.Premissas Receitas'!$B$19) -> 1.3842339 | S9: =R9+(R9*'1.Premissas Receitas'!$G$16) -> 1.9379274 | T9: =S9+(S9*'1.Premissas Receitas'!$B$19) -> 1.9960652 | U9: =T9+(T9*'1.Premissas Receitas'!$B$19) -> 2.0559472 | V9: =U9+(U9*'1.Premissas Receitas'!$B$19) -> 2.1176256 | W9: =V9+(V9*'1.Premissas Receitas'!$B$19) -> 2.1811544 | X9: =W9+(W9*'1.Premissas Receitas'!$B$19) -> 2.246589 | Y9: =X9+(X9*'1.Premissas Receitas'!$B$19) -> 2.3139867 | Z9: =Y9+(Y9*'1.Premissas Receitas'!$B$19) -> 2.3834063 | AA9: =Z9+(Z9*'1.Premissas Receitas'!$B$19) -> 2.4549085 | ... AD9: =AC9+(AC9*'1.Premissas Receitas'!$B$19) -> 2.6825448 | AE9: =AD9+(AD9*'1.Premissas Receitas'!$G$17) -> 3.4873082 | AF9: =AE9+(AE9*'1.Premissas Receitas'!$B$19) -> 3.5919275 | AG9: =AF9+(AF9*'1.Premissas Receitas'!$B$19) -> 3.6996853 | AH9: =AG9+(AG9*'1.Premissas Receitas'!$B$19) -> 3.8106758 | AI9: =AH9+(AH9*'1.Premissas Receitas'!$B$19) -> 3.9249961 | AJ9: =AI9+(AI9*'1.Premissas Receitas'!$B$19) -> 4.042746 | AK9: =AJ9+(AJ9*'1.Premissas Receitas'!$B$19) -> 4.1640284 | AL9: =AK9+(AK9*'1.Premissas Receitas'!$B$19) -> 4.2889492 | AM9: =AL9+(AL9*'1.Premissas Receitas'!$B$19) -> 4.4176177 | ... AP9: =AO9+(AO9*'1.Premissas Receitas'!$B$19) -> 4.8272501 | AQ9: =AP9+(AP9*'1.Premissas Receitas'!$G$18) -> 5.7927002 | AR9: =AQ9+(AQ9*'1.Premissas Receitas'!$B$19) -> 5.9664812 | AS9: =AR9+(AR9*'1.Premissas Receitas'!$B$19) -> 6.1454756 | AT9: =AS9+(AS9*'1.Premissas Receitas'!$B$19) -> 6.3298399 | AU9: =AT9+(AT9*'1.Premissas Receitas'!$B$19) -> 6.5197351 | AV9: =AU9+(AU9*'1.Premissas Receitas'!$B$19) -> 6.7153271 | AW9: =AV9+(AV9*'1.Premissas Receitas'!$B$19) -> 6.9167869 | AX9: =AW9+(AW9*'1.Premissas Receitas'!$B$19) -> 7.1242905 | AY9: =AX9+(AX9*'1.Premissas Receitas'!$B$19) -> 7.3380193 | ... BB9: =BA9+(BA9*'1.Premissas Receitas'!$B$19) -> 8.0184518 | BC9: =BB9+(BB9*'1.Premissas Receitas'!$G$19) -> 9.2212195 | BD9: =BC9+(BC9*'1.Premissas Receitas'!$B$19) -> 9.4978561 | BE9: =BD9+(BD9*'1.Premissas Receitas'!$B$19) -> 9.7827918 | BF9: =BE9+(BE9*'1.Premissas Receitas'!$B$19) -> 10.076276 | BG9: =BF9+(BF9*'1.Premissas Receitas'!$B$19) -> 10.378564 | BH9: =BG9+(BG9*'1.Premissas Receitas'!$B$19) -> 10.689921 | BI9: =BH9+(BH9*'1.Premissas Receitas'!$B$19) -> 11.010618 | BJ9: =BI9+(BI9*'1.Premissas Receitas'!$B$19) -> 11.340937 | BK9: =BJ9+(BJ9*'1.Premissas Receitas'!$B$19) -> 11.681165 | ... BN9: =BM9+(BM9*'1.Premissas Receitas'!$B$19) -> 12.764324 | BP9: =SUM(G9:R9) -> 14.19203 | BQ9: =SUM(T9:AD9) -> 25.565196 | BR9: =SUM(AE9:AP9) -> 49.491981 | BS9: =SUM(AQ9:BB9) -> 82.210172 | BT9: =SUM(BC9:BN9) -> 130.86782
C10: ='1.Premissas Receitas'!A26 -> # de clientes Assinatura 1 | G10: ='1.Premissas Receitas'!G26 -> 0.7 | H10: =G10+(G10*'1.Premissas Receitas'!$B$19) -> 0.721 | I10: =H10+(H10*'1.Premissas Receitas'!$B$19) -> 0.74263 | J10: =I10+(I10*'1.Premissas Receitas'!$B$19) -> 0.7649089 | K10: =J10+(J10*'1.Premissas Receitas'!$B$19) -> 0.78785617 | L10: =K10+(K10*'1.Premissas Receitas'!$B$19) -> 0.81149185 | M10: =L10+(L10*'1.Premissas Receitas'!$B$19) -> 0.83583661 | N10: =M10+(M10*'1.Premissas Receitas'!$B$19) -> 0.86091171 | O10: =N10+(N10*'1.Premissas Receitas'!$B$19) -> 0.88673906 | ... R10: =Q10+(Q10*'1.Premissas Receitas'!$B$19) -> 0.96896371 | S10: =R10+(R10*'1.Premissas Receitas'!$G$16) -> 1.3565492 | T10: =S10+(S10*'1.Premissas Receitas'!$B$19) -> 1.3972457 | U10: =T10+(T10*'1.Premissas Receitas'!$B$19) -> 1.439163 | V10: =U10+(U10*'1.Premissas Receitas'!$B$19) -> 1.4823379 | W10: =V10+(V10*'1.Premissas Receitas'!$B$19) -> 1.5268081 | X10: =W10+(W10*'1.Premissas Receitas'!$B$19) -> 1.5726123 | Y10: =X10+(X10*'1.Premissas Receitas'!$B$19) -> 1.6197907 | Z10: =Y10+(Y10*'1.Premissas Receitas'!$B$19) -> 1.6683844 | AA10: =Z10+(Z10*'1.Premissas Receitas'!$B$19) -> 1.7184359 | ... AD10: =AC10+(AC10*'1.Premissas Receitas'!$B$19) -> 1.8777813 | AE10: =AD10+(AD10*'1.Premissas Receitas'!$G$17) -> 2.4411157 | AF10: =AE10+(AE10*'1.Premissas Receitas'!$B$19) -> 2.5143492 | AG10: =AF10+(AF10*'1.Premissas Receitas'!$B$19) -> 2.5897797 | AH10: =AG10+(AG10*'1.Premissas Receitas'!$B$19) -> 2.6674731 | AI10: =AH10+(AH10*'1.Premissas Receitas'!$B$19) -> 2.7474973 | AJ10: =AI10+(AI10*'1.Premissas Receitas'!$B$19) -> 2.8299222 | AK10: =AJ10+(AJ10*'1.Premissas Receitas'!$B$19) -> 2.9148199 | AL10: =AK10+(AK10*'1.Premissas Receitas'!$B$19) -> 3.0022645 | AM10: =AL10+(AL10*'1.Premissas Receitas'!$B$19) -> 3.0923324 | ... AP10: =AO10+(AO10*'1.Premissas Receitas'!$B$19) -> 3.3790751 | AQ10: =AP10+(AP10*'1.Premissas Receitas'!$G$18) -> 4.0548901 | AR10: =AQ10+(AQ10*'1.Premissas Receitas'!$B$19) -> 4.1765368 | AS10: =AR10+(AR10*'1.Premissas Receitas'!$B$19) -> 4.3018329 | AT10: =AS10+(AS10*'1.Premissas Receitas'!$B$19) -> 4.4308879 | AU10: =AT10+(AT10*'1.Premissas Receitas'!$B$19) -> 4.5638145 | AV10: =AU10+(AU10*'1.Premissas Receitas'!$B$19) -> 4.700729 | AW10: =AV10+(AV10*'1.Premissas Receitas'!$B$19) -> 4.8417509 | AX10: =AW10+(AW10*'1.Premissas Receitas'!$B$19) -> 4.9870034 | AY10: =AX10+(AX10*'1.Premissas Receitas'!$B$19) -> 5.1366135 | ... BB10: =BA10+(BA10*'1.Premissas Receitas'!$B$19) -> 5.6129162 | BC10: =BB10+(BB10*'1.Premissas Receitas'!$G$19) -> 6.4548537 | BD10: =BC10+(BC10*'1.Premissas Receitas'!$B$19) -> 6.6484993 | BE10: =BD10+(BD10*'1.Premissas Receitas'!$B$19) -> 6.8479543 | BF10: =BE10+(BE10*'1.Premissas Receitas'!$B$19) -> 7.0533929 | BG10: =BF10+(BF10*'1.Premissas Receitas'!$B$19) -> 7.2649947 | BH10: =BG10+(BG10*'1.Premissas Receitas'!$B$19) -> 7.4829445 | BI10: =BH10+(BH10*'1.Premissas Receitas'!$B$19) -> 7.7074328 | BJ10: =BI10+(BI10*'1.Premissas Receitas'!$B$19) -> 7.9386558 | BK10: =BJ10+(BJ10*'1.Premissas Receitas'!$B$19) -> 8.1768155 | ... BN10: =BM10+(BM10*'1.Premissas Receitas'!$B$19) -> 8.9350271 | BP10: =SUM(G10:R10) -> 9.9344207 | BQ10: =SUM(T10:AD10) -> 17.895637 | BR10: =SUM(AE10:AP10) -> 34.644387 | BS10: =SUM(AQ10:BB10) -> 57.54712 | BT10: =SUM(BC10:BN10) -> 91.607474
C11: ='1.Premissas Receitas'!A27 -> # de clientes Assinatura 2 | G11: ='1.Premissas Receitas'!G27 -> 0.3 | H11: =G11+(G11*'1.Premissas Receitas'!$B$19) -> 0.309 | I11: =H11+(H11*'1.Premissas Receitas'!$B$19) -> 0.31827 | J11: =I11+(I11*'1.Premissas Receitas'!$B$19) -> 0.3278181 | K11: =J11+(J11*'1.Premissas Receitas'!$B$19) -> 0.33765264 | L11: =K11+(K11*'1.Premissas Receitas'!$B$19) -> 0.34778222 | M11: =L11+(L11*'1.Premissas Receitas'!$B$19) -> 0.35821569 | N11: =M11+(M11*'1.Premissas Receitas'!$B$19) -> 0.36896216 | O11: =N11+(N11*'1.Premissas Receitas'!$B$19) -> 0.38003102 | ... R11: =Q11+(Q11*'1.Premissas Receitas'!$B$19) -> 0.41527016 | S11: =R11+(R11*'1.Premissas Receitas'!$G$16) -> 0.58137823 | T11: =S11+(S11*'1.Premissas Receitas'!$B$19) -> 0.59881957 | U11: =T11+(T11*'1.Premissas Receitas'!$B$19) -> 0.61678416 | V11: =U11+(U11*'1.Premissas Receitas'!$B$19) -> 0.63528768 | W11: =V11+(V11*'1.Premissas Receitas'!$B$19) -> 0.65434631 | X11: =W11+(W11*'1.Premissas Receitas'!$B$19) -> 0.6739767 | Y11: =X11+(X11*'1.Premissas Receitas'!$B$19) -> 0.69419601 | Z11: =Y11+(Y11*'1.Premissas Receitas'!$B$19) -> 0.71502189 | AA11: =Z11+(Z11*'1.Premissas Receitas'!$B$19) -> 0.73647254 | ... AD11: =AC11+(AC11*'1.Premissas Receitas'!$B$19) -> 0.80476343 | AE11: =AD11+(AD11*'1.Premissas Receitas'!$G$17) -> 1.0461925 | AF11: =AE11+(AE11*'1.Premissas Receitas'!$B$19) -> 1.0775782 | AG11: =AF11+(AF11*'1.Premissas Receitas'!$B$19) -> 1.1099056 | AH11: =AG11+(AG11*'1.Premissas Receitas'!$B$19) -> 1.1432027 | AI11: =AH11+(AH11*'1.Premissas Receitas'!$B$19) -> 1.1774988 | AJ11: =AI11+(AI11*'1.Premissas Receitas'!$B$19) -> 1.2128238 | AK11: =AJ11+(AJ11*'1.Premissas Receitas'!$B$19) -> 1.2492085 | AL11: =AK11+(AK11*'1.Premissas Receitas'!$B$19) -> 1.2866848 | AM11: =AL11+(AL11*'1.Premissas Receitas'!$B$19) -> 1.3252853 | ... AP11: =AO11+(AO11*'1.Premissas Receitas'!$B$19) -> 1.448175 | AQ11: =AP11+(AP11*'1.Premissas Receitas'!$G$18) -> 1.73781 | AR11: =AQ11+(AQ11*'1.Premissas Receitas'!$B$19) -> 1.7899443 | AS11: =AR11+(AR11*'1.Premissas Receitas'!$B$19) -> 1.8436427 | AT11: =AS11+(AS11*'1.Premissas Receitas'!$B$19) -> 1.898952 | AU11: =AT11+(AT11*'1.Premissas Receitas'!$B$19) -> 1.9559205 | AV11: =AU11+(AU11*'1.Premissas Receitas'!$B$19) -> 2.0145981 | AW11: =AV11+(AV11*'1.Premissas Receitas'!$B$19) -> 2.0750361 | AX11: =AW11+(AW11*'1.Premissas Receitas'!$B$19) -> 2.1372872 | AY11: =AX11+(AX11*'1.Premissas Receitas'!$B$19) -> 2.2014058 | ... BB11: =BA11+(BA11*'1.Premissas Receitas'!$B$19) -> 2.4055355 | BC11: =BB11+(BB11*'1.Premissas Receitas'!$G$19) -> 2.7663659 | BD11: =BC11+(BC11*'1.Premissas Receitas'!$B$19) -> 2.8493568 | BE11: =BD11+(BD11*'1.Premissas Receitas'!$B$19) -> 2.9348375 | BF11: =BE11+(BE11*'1.Premissas Receitas'!$B$19) -> 3.0228827 | BG11: =BF11+(BF11*'1.Premissas Receitas'!$B$19) -> 3.1135691 | BH11: =BG11+(BG11*'1.Premissas Receitas'!$B$19) -> 3.2069762 | BI11: =BH11+(BH11*'1.Premissas Receitas'!$B$19) -> 3.3031855 | BJ11: =BI11+(BI11*'1.Premissas Receitas'!$B$19) -> 3.4022811 | BK11: =BJ11+(BJ11*'1.Premissas Receitas'!$B$19) -> 3.5043495 | ... BN11: =BM11+(BM11*'1.Premissas Receitas'!$B$19) -> 3.8292973 | BP11: =SUM(G11:R11) -> 4.2576089 | BQ11: =SUM(T11:AD11) -> 7.6695587 | BR11: =SUM(AE11:AP11) -> 14.847594 | BS11: =SUM(AQ11:BB11) -> 24.663052 | BT11: =SUM(BC11:BN11) -> 39.260346
C12: ='1.Premissas Receitas'!A33 -> # de clientes marketplace % Comissão 1 | G12: ='1.Premissas Receitas'!G33 -> 0 | H12: =G12+(G12*'1.Premissas Receitas'!$B$19) -> 0 | I12: =H12+(H12*'1.Premissas Receitas'!$B$19) -> 0 | J12: =I12+(I12*'1.Premissas Receitas'!$B$19) -> 0 | K12: =J12+(J12*'1.Premissas Receitas'!$B$19) -> 0 | L12: =K12+(K12*'1.Premissas Receitas'!$B$19) -> 0 | M12: =L12+(L12*'1.Premissas Receitas'!$B$19) -> 0 | N12: =M12+(M12*'1.Premissas Receitas'!$B$19) -> 0 | O12: =N12+(N12*'1.Premissas Receitas'!$B$19) -> 0 | ... R12: =Q12+(Q12*'1.Premissas Receitas'!$B$19) -> 0 | S12: =R12+(R12*'1.Premissas Receitas'!$G$16) -> 0 | T12: =S12+(S12*'1.Premissas Receitas'!$B$19) -> 0 | U12: =T12+(T12*'1.Premissas Receitas'!$B$19) -> 0 | V12: =U12+(U12*'1.Premissas Receitas'!$B$19) -> 0 | W12: =V12+(V12*'1.Premissas Receitas'!$B$19) -> 0 | X12: =W12+(W12*'1.Premissas Receitas'!$B$19) -> 0 | Y12: =X12+(X12*'1.Premissas Receitas'!$B$19) -> 0 | Z12: =Y12+(Y12*'1.Premissas Receitas'!$B$19) -> 0 | AA12: =Z12+(Z12*'1.Premissas Receitas'!$B$19) -> 0 | ... AD12: =AC12+(AC12*'1.Premissas Receitas'!$B$19) -> 0 | AE12: =AD12+(AD12*'1.Premissas Receitas'!$G$17) -> 0 | AF12: =AE12+(AE12*'1.Premissas Receitas'!$B$19) -> 0 | AG12: =AF12+(AF12*'1.Premissas Receitas'!$B$19) -> 0 | AH12: =AG12+(AG12*'1.Premissas Receitas'!$B$19) -> 0 | AI12: =AH12+(AH12*'1.Premissas Receitas'!$B$19) -> 0 | AJ12: =AI12+(AI12*'1.Premissas Receitas'!$B$19) -> 0 | AK12: =AJ12+(AJ12*'1.Premissas Receitas'!$B$19) -> 0 | AL12: =AK12+(AK12*'1.Premissas Receitas'!$B$19) -> 0 | AM12: =AL12+(AL12*'1.Premissas Receitas'!$B$19) -> 0 | ... AP12: =AO12+(AO12*'1.Premissas Receitas'!$B$19) -> 0 | AQ12: =AP12+(AP12*'1.Premissas Receitas'!$G$18) -> 0 | AR12: =AQ12+(AQ12*'1.Premissas Receitas'!$B$19) -> 0 | AS12: =AR12+(AR12*'1.Premissas Receitas'!$B$19) -> 0 | AT12: =AS12+(AS12*'1.Premissas Receitas'!$B$19) -> 0 | AU12: =AT12+(AT12*'1.Premissas Receitas'!$B$19) -> 0 | AV12: =AU12+(AU12*'1.Premissas Receitas'!$B$19) -> 0 | AW12: =AV12+(AV12*'1.Premissas Receitas'!$B$19) -> 0 | AX12: =AW12+(AW12*'1.Premissas Receitas'!$B$19) -> 0 | AY12: =AX12+(AX12*'1.Premissas Receitas'!$B$19) -> 0 | ... BB12: =BA12+(BA12*'1.Premissas Receitas'!$B$19) -> 0 | BC12: =BB12+(BB12*'1.Premissas Receitas'!$G$19) -> 0 | BD12: =BC12+(BC12*'1.Premissas Receitas'!$B$19) -> 0 | BE12: =BD12+(BD12*'1.Premissas Receitas'!$B$19) -> 0 | BF12: =BE12+(BE12*'1.Premissas Receitas'!$B$19) -> 0 | BG12: =BF12+(BF12*'1.Premissas Receitas'!$B$19) -> 0 | BH12: =BG12+(BG12*'1.Premissas Receitas'!$B$19) -> 0 | BI12: =BH12+(BH12*'1.Premissas Receitas'!$B$19) -> 0 | BJ12: =BI12+(BI12*'1.Premissas Receitas'!$B$19) -> 0 | BK12: =BJ12+(BJ12*'1.Premissas Receitas'!$B$19) -> 0 | ... BN12: =BM12+(BM12*'1.Premissas Receitas'!$B$19) -> 0 | BP12: =SUM(G12:R12) -> 0 | BQ12: =SUM(T12:AD12) -> 0 | BR12: =SUM(AE12:AP12) -> 0 | BS12: =SUM(AQ12:BB12) -> 0 | BT12: =SUM(BC12:BN12) -> 0
C13: ='1.Premissas Receitas'!A34 -> # de clientes marketplace % Comissão 2 | G13: ='1.Premissas Receitas'!G34 -> 0 | H13: =G13+(G13*'1.Premissas Receitas'!$B$19) -> 0 | I13: =H13+(H13*'1.Premissas Receitas'!$B$19) -> 0 | J13: =I13+(I13*'1.Premissas Receitas'!$B$19) -> 0 | K13: =J13+(J13*'1.Premissas Receitas'!$B$19) -> 0 | L13: =K13+(K13*'1.Premissas Receitas'!$B$19) -> 0 | M13: =L13+(L13*'1.Premissas Receitas'!$B$19) -> 0 | N13: =M13+(M13*'1.Premissas Receitas'!$B$19) -> 0 | O13: =N13+(N13*'1.Premissas Receitas'!$B$19) -> 0 | ... R13: =Q13+(Q13*'1.Premissas Receitas'!$B$19) -> 0 | S13: =R13+(R13*'1.Premissas Receitas'!$G$16) -> 0 | T13: =S13+(S13*'1.Premissas Receitas'!$B$19) -> 0 | U13: =T13+(T13*'1.Premissas Receitas'!$B$19) -> 0 | V13: =U13+(U13*'1.Premissas Receitas'!$B$19) -> 0 | W13: =V13+(V13*'1.Premissas Receitas'!$B$19) -> 0 | X13: =W13+(W13*'1.Premissas Receitas'!$B$19) -> 0 | Y13: =X13+(X13*'1.Premissas Receitas'!$B$19) -> 0 | Z13: =Y13+(Y13*'1.Premissas Receitas'!$B$19) -> 0 | AA13: =Z13+(Z13*'1.Premissas Receitas'!$B$19) -> 0 | ... AD13: =AC13+(AC13*'1.Premissas Receitas'!$B$19) -> 0 | AE13: =AD13+(AD13*'1.Premissas Receitas'!$G$17) -> 0 | AF13: =AE13+(AE13*'1.Premissas Receitas'!$B$19) -> 0 | AG13: =AF13+(AF13*'1.Premissas Receitas'!$B$19) -> 0 | AH13: =AG13+(AG13*'1.Premissas Receitas'!$B$19) -> 0 | AI13: =AH13+(AH13*'1.Premissas Receitas'!$B$19) -> 0 | AJ13: =AI13+(AI13*'1.Premissas Receitas'!$B$19) -> 0 | AK13: =AJ13+(AJ13*'1.Premissas Receitas'!$B$19) -> 0 | AL13: =AK13+(AK13*'1.Premissas Receitas'!$B$19) -> 0 | AM13: =AL13+(AL13*'1.Premissas Receitas'!$B$19) -> 0 | ... AP13: =AO13+(AO13*'1.Premissas Receitas'!$B$19) -> 0 | AQ13: =AP13+(AP13*'1.Premissas Receitas'!$G$18) -> 0 | AR13: =AQ13+(AQ13*'1.Premissas Receitas'!$B$19) -> 0 | AS13: =AR13+(AR13*'1.Premissas Receitas'!$B$19) -> 0 | AT13: =AS13+(AS13*'1.Premissas Receitas'!$B$19) -> 0 | AU13: =AT13+(AT13*'1.Premissas Receitas'!$B$19) -> 0 | AV13: =AU13+(AU13*'1.Premissas Receitas'!$B$19) -> 0 | AW13: =AV13+(AV13*'1.Premissas Receitas'!$B$19) -> 0 | AX13: =AW13+(AW13*'1.Premissas Receitas'!$B$19) -> 0 | AY13: =AX13+(AX13*'1.Premissas Receitas'!$B$19) -> 0 | ... BB13: =BA13+(BA13*'1.Premissas Receitas'!$B$19) -> 0 | BC13: =BB13+(BB13*'1.Premissas Receitas'!$G$19) -> 0 | BD13: =BC13+(BC13*'1.Premissas Receitas'!$B$19) -> 0 | BE13: =BD13+(BD13*'1.Premissas Receitas'!$B$19) -> 0 | BF13: =BE13+(BE13*'1.Premissas Receitas'!$B$19) -> 0 | BG13: =BF13+(BF13*'1.Premissas Receitas'!$B$19) -> 0 | BH13: =BG13+(BG13*'1.Premissas Receitas'!$B$19) -> 0 | BI13: =BH13+(BH13*'1.Premissas Receitas'!$B$19) -> 0 | BJ13: =BI13+(BI13*'1.Premissas Receitas'!$B$19) -> 0 | BK13: =BJ13+(BJ13*'1.Premissas Receitas'!$B$19) -> 0 | ... BN13: =BM13+(BM13*'1.Premissas Receitas'!$B$19) -> 0 | BP13: =SUM(G13:R13) -> 0 | BQ13: =SUM(T13:AD13) -> 0 | BR13: =SUM(AE13:AP13) -> 0 | BS13: =SUM(AQ13:BB13) -> 0 | BT13: =SUM(BC13:BN13) -> 0
C14: ='1.Premissas Receitas'!A35 -> # de clientes marketplace % Comissão 3 | G14: ='1.Premissas Receitas'!G35 -> 0 | H14: =G14+(G14*'1.Premissas Receitas'!$B$19) -> 0 | I14: =H14+(H14*'1.Premissas Receitas'!$B$19) -> 0 | J14: =I14+(I14*'1.Premissas Receitas'!$B$19) -> 0 | K14: =J14+(J14*'1.Premissas Receitas'!$B$19) -> 0 | L14: =K14+(K14*'1.Premissas Receitas'!$B$19) -> 0 | M14: =L14+(L14*'1.Premissas Receitas'!$B$19) -> 0 | N14: =M14+(M14*'1.Premissas Receitas'!$B$19) -> 0 | O14: =N14+(N14*'1.Premissas Receitas'!$B$19) -> 0 | ... R14: =Q14+(Q14*'1.Premissas Receitas'!$B$19) -> 0 | S14: =R14+(R14*'1.Premissas Receitas'!$G$16) -> 0 | T14: =S14+(S14*'1.Premissas Receitas'!$B$19) -> 0 | U14: =T14+(T14*'1.Premissas Receitas'!$B$19) -> 0 | V14: =U14+(U14*'1.Premissas Receitas'!$B$19) -> 0 | W14: =V14+(V14*'1.Premissas Receitas'!$B$19) -> 0 | X14: =W14+(W14*'1.Premissas Receitas'!$B$19) -> 0 | Y14: =X14+(X14*'1.Premissas Receitas'!$B$19) -> 0 | Z14: =Y14+(Y14*'1.Premissas Receitas'!$B$19) -> 0 | AA14: =Z14+(Z14*'1.Premissas Receitas'!$B$19) -> 0 | ... AD14: =AC14+(AC14*'1.Premissas Receitas'!$B$19) -> 0 | AE14: =AD14+(AD14*'1.Premissas Receitas'!$G$17) -> 0 | AF14: =AE14+(AE14*'1.Premissas Receitas'!$B$19) -> 0 | AG14: =AF14+(AF14*'1.Premissas Receitas'!$B$19) -> 0 | AH14: =AG14+(AG14*'1.Premissas Receitas'!$B$19) -> 0 | AI14: =AH14+(AH14*'1.Premissas Receitas'!$B$19) -> 0 | AJ14: =AI14+(AI14*'1.Premissas Receitas'!$B$19) -> 0 | AK14: =AJ14+(AJ14*'1.Premissas Receitas'!$B$19) -> 0 | AL14: =AK14+(AK14*'1.Premissas Receitas'!$B$19) -> 0 | AM14: =AL14+(AL14*'1.Premissas Receitas'!$B$19) -> 0 | ... AP14: =AO14+(AO14*'1.Premissas Receitas'!$B$19) -> 0 | AQ14: =AP14+(AP14*'1.Premissas Receitas'!$G$18) -> 0 | AR14: =AQ14+(AQ14*'1.Premissas Receitas'!$B$19) -> 0 | AS14: =AR14+(AR14*'1.Premissas Receitas'!$B$19) -> 0 | AT14: =AS14+(AS14*'1.Premissas Receitas'!$B$19) -> 0 | AU14: =AT14+(AT14*'1.Premissas Receitas'!$B$19) -> 0 | AV14: =AU14+(AU14*'1.Premissas Receitas'!$B$19) -> 0 | AW14: =AV14+(AV14*'1.Premissas Receitas'!$B$19) -> 0 | AX14: =AW14+(AW14*'1.Premissas Receitas'!$B$19) -> 0 | AY14: =AX14+(AX14*'1.Premissas Receitas'!$B$19) -> 0 | ... BB14: =BA14+(BA14*'1.Premissas Receitas'!$B$19) -> 0 | BC14: =BB14+(BB14*'1.Premissas Receitas'!$G$19) -> 0 | BD14: =BC14+(BC14*'1.Premissas Receitas'!$B$19) -> 0 | BE14: =BD14+(BD14*'1.Premissas Receitas'!$B$19) -> 0 | BF14: =BE14+(BE14*'1.Premissas Receitas'!$B$19) -> 0 | BG14: =BF14+(BF14*'1.Premissas Receitas'!$B$19) -> 0 | BH14: =BG14+(BG14*'1.Premissas Receitas'!$B$19) -> 0 | BI14: =BH14+(BH14*'1.Premissas Receitas'!$B$19) -> 0 | BJ14: =BI14+(BI14*'1.Premissas Receitas'!$B$19) -> 0 | BK14: =BJ14+(BJ14*'1.Premissas Receitas'!$B$19) -> 0 | ... BN14: =BM14+(BM14*'1.Premissas Receitas'!$B$19) -> 0 | BP14: =SUM(G14:R14) -> 0 | BQ14: =SUM(T14:AD14) -> 0 | BR14: =SUM(AE14:AP14) -> 0 | BS14: =SUM(AQ14:BB14) -> 0 | BT14: =SUM(BC14:BN14) -> 0
C15: ='1.Premissas Receitas'!A40 -> # de clientes B2B Setup | G15: ='1.Premissas Receitas'!G40 -> 1.3333333 | H15: =G15+(G15*'1.Premissas Receitas'!$B$19) -> 1.3733333 | I15: =H15+(H15*'1.Premissas Receitas'!$B$19) -> 1.4145333 | J15: =I15+(I15*'1.Premissas Receitas'!$B$19) -> 1.4569693 | K15: =J15+(J15*'1.Premissas Receitas'!$B$19) -> 1.5006784 | L15: =K15+(K15*'1.Premissas Receitas'!$B$19) -> 1.5456988 | M15: =L15+(L15*'1.Premissas Receitas'!$B$19) -> 1.5920697 | N15: =M15+(M15*'1.Premissas Receitas'!$B$19) -> 1.6398318 | O15: =N15+(N15*'1.Premissas Receitas'!$B$19) -> 1.6890268 | ... R15: =Q15+(Q15*'1.Premissas Receitas'!$B$19) -> 1.8456452 | S15: =R15+(R15*'1.Premissas Receitas'!$G$16) -> 2.5839032 | T15: =S15+(S15*'1.Premissas Receitas'!$B$19) -> 2.6614203 | U15: =T15+(T15*'1.Premissas Receitas'!$B$19) -> 2.7412629 | V15: =U15+(U15*'1.Premissas Receitas'!$B$19) -> 2.8235008 | W15: =V15+(V15*'1.Premissas Receitas'!$B$19) -> 2.9082058 | X15: =W15+(W15*'1.Premissas Receitas'!$B$19) -> 2.995452 | Y15: =X15+(X15*'1.Premissas Receitas'!$B$19) -> 3.0853156 | Z15: =Y15+(Y15*'1.Premissas Receitas'!$B$19) -> 3.177875 | AA15: =Z15+(Z15*'1.Premissas Receitas'!$B$19) -> 3.2732113 | ... AD15: =AC15+(AC15*'1.Premissas Receitas'!$B$19) -> 3.5767264 | AE15: =AD15+(AD15*'1.Premissas Receitas'!$G$17) -> 4.6497443 | AF15: =AE15+(AE15*'1.Premissas Receitas'!$B$19) -> 4.7892366 | AG15: =AF15+(AF15*'1.Premissas Receitas'!$B$19) -> 4.9329137 | AH15: =AG15+(AG15*'1.Premissas Receitas'!$B$19) -> 5.0809011 | AI15: =AH15+(AH15*'1.Premissas Receitas'!$B$19) -> 5.2333281 | AJ15: =AI15+(AI15*'1.Premissas Receitas'!$B$19) -> 5.390328 | AK15: =AJ15+(AJ15*'1.Premissas Receitas'!$B$19) -> 5.5520378 | AL15: =AK15+(AK15*'1.Premissas Receitas'!$B$19) -> 5.718599 | AM15: =AL15+(AL15*'1.Premissas Receitas'!$B$19) -> 5.8901569 | ... AP15: =AO15+(AO15*'1.Premissas Receitas'!$B$19) -> 6.4363335 | AQ15: =AP15+(AP15*'1.Premissas Receitas'!$G$18) -> 7.7236002 | AR15: =AQ15+(AQ15*'1.Premissas Receitas'!$B$19) -> 7.9553082 | AS15: =AR15+(AR15*'1.Premissas Receitas'!$B$19) -> 8.1939675 | AT15: =AS15+(AS15*'1.Premissas Receitas'!$B$19) -> 8.4397865 | AU15: =AT15+(AT15*'1.Premissas Receitas'!$B$19) -> 8.6929801 | AV15: =AU15+(AU15*'1.Premissas Receitas'!$B$19) -> 8.9537695 | AW15: =AV15+(AV15*'1.Premissas Receitas'!$B$19) -> 9.2223826 | AX15: =AW15+(AW15*'1.Premissas Receitas'!$B$19) -> 9.4990541 | AY15: =AX15+(AX15*'1.Premissas Receitas'!$B$19) -> 9.7840257 | ... BB15: =BA15+(BA15*'1.Premissas Receitas'!$B$19) -> 10.691269 | BC15: =BB15+(BB15*'1.Premissas Receitas'!$G$19) -> 12.294959 | BD15: =BC15+(BC15*'1.Premissas Receitas'!$B$19) -> 12.663808 | BE15: =BD15+(BD15*'1.Premissas Receitas'!$B$19) -> 13.043722 | BF15: =BE15+(BE15*'1.Premissas Receitas'!$B$19) -> 13.435034 | BG15: =BF15+(BF15*'1.Premissas Receitas'!$B$19) -> 13.838085 | BH15: =BG15+(BG15*'1.Premissas Receitas'!$B$19) -> 14.253228 | BI15: =BH15+(BH15*'1.Premissas Receitas'!$B$19) -> 14.680824 | BJ15: =BI15+(BI15*'1.Premissas Receitas'!$B$19) -> 15.121249 | BK15: =BJ15+(BJ15*'1.Premissas Receitas'!$B$19) -> 15.574887 | ... BN15: =BM15+(BM15*'1.Premissas Receitas'!$B$19) -> 17.019099 | BP15: =SUM(G15:R15) -> 18.922706 | BQ15: =SUM(T15:AD15) -> 34.086928 | BR15: =SUM(AE15:AP15) -> 65.989308 | BS15: =SUM(AQ15:BB15) -> 109.61356 | BT15: =SUM(BC15:BN15) -> 174.49043
C16: ='1.Premissas Receitas'!A41 -> # de clientes B2B Mensalidade | G16: ='1.Premissas Receitas'!G41 -> 1.3333333 | H16: =G16+(G16*'1.Premissas Receitas'!$B$19) -> 1.3733333 | I16: =H16+(H16*'1.Premissas Receitas'!$B$19) -> 1.4145333 | J16: =I16+(I16*'1.Premissas Receitas'!$B$19) -> 1.4569693 | K16: =J16+(J16*'1.Premissas Receitas'!$B$19) -> 1.5006784 | L16: =K16+(K16*'1.Premissas Receitas'!$B$19) -> 1.5456988 | M16: =L16+(L16*'1.Premissas Receitas'!$B$19) -> 1.5920697 | N16: =M16+(M16*'1.Premissas Receitas'!$B$19) -> 1.6398318 | O16: =N16+(N16*'1.Premissas Receitas'!$B$19) -> 1.6890268 | ... R16: =Q16+(Q16*'1.Premissas Receitas'!$B$19) -> 1.8456452 | S16: =R16+(R16*'1.Premissas Receitas'!$G$16) -> 2.5839032 | T16: =S16+(S16*'1.Premissas Receitas'!$B$19) -> 2.6614203 | U16: =T16+(T16*'1.Premissas Receitas'!$B$19) -> 2.7412629 | V16: =U16+(U16*'1.Premissas Receitas'!$B$19) -> 2.8235008 | W16: =V16+(V16*'1.Premissas Receitas'!$B$19) -> 2.9082058 | X16: =W16+(W16*'1.Premissas Receitas'!$B$19) -> 2.995452 | Y16: =X16+(X16*'1.Premissas Receitas'!$B$19) -> 3.0853156 | Z16: =Y16+(Y16*'1.Premissas Receitas'!$B$19) -> 3.177875 | AA16: =Z16+(Z16*'1.Premissas Receitas'!$B$19) -> 3.2732113 | ... AD16: =AC16+(AC16*'1.Premissas Receitas'!$B$19) -> 3.5767264 | AE16: =AD16+(AD16*'1.Premissas Receitas'!$G$17) -> 4.6497443 | AF16: =AE16+(AE16*'1.Premissas Receitas'!$B$19) -> 4.7892366 | AG16: =AF16+(AF16*'1.Premissas Receitas'!$B$19) -> 4.9329137 | AH16: =AG16+(AG16*'1.Premissas Receitas'!$B$19) -> 5.0809011 | AI16: =AH16+(AH16*'1.Premissas Receitas'!$B$19) -> 5.2333281 | AJ16: =AI16+(AI16*'1.Premissas Receitas'!$B$19) -> 5.390328 | AK16: =AJ16+(AJ16*'1.Premissas Receitas'!$B$19) -> 5.5520378 | AL16: =AK16+(AK16*'1.Premissas Receitas'!$B$19) -> 5.718599 | AM16: =AL16+(AL16*'1.Premissas Receitas'!$B$19) -> 5.8901569 | ... AP16: =AO16+(AO16*'1.Premissas Receitas'!$B$19) -> 6.4363335 | AQ16: =AP16+(AP16*'1.Premissas Receitas'!$G$18) -> 7.7236002 | AR16: =AQ16+(AQ16*'1.Premissas Receitas'!$B$19) -> 7.9553082 | AS16: =AR16+(AR16*'1.Premissas Receitas'!$B$19) -> 8.1939675 | AT16: =AS16+(AS16*'1.Premissas Receitas'!$B$19) -> 8.4397865 | AU16: =AT16+(AT16*'1.Premissas Receitas'!$B$19) -> 8.6929801 | AV16: =AU16+(AU16*'1.Premissas Receitas'!$B$19) -> 8.9537695 | AW16: =AV16+(AV16*'1.Premissas Receitas'!$B$19) -> 9.2223826 | AX16: =AW16+(AW16*'1.Premissas Receitas'!$B$19) -> 9.4990541 | AY16: =AX16+(AX16*'1.Premissas Receitas'!$B$19) -> 9.7840257 | ... BB16: =BA16+(BA16*'1.Premissas Receitas'!$B$19) -> 10.691269 | BC16: =BB16+(BB16*'1.Premissas Receitas'!$G$19) -> 12.294959 | BD16: =BC16+(BC16*'1.Premissas Receitas'!$B$19) -> 12.663808 | BE16: =BD16+(BD16*'1.Premissas Receitas'!$B$19) -> 13.043722 | BF16: =BE16+(BE16*'1.Premissas Receitas'!$B$19) -> 13.435034 | BG16: =BF16+(BF16*'1.Premissas Receitas'!$B$19) -> 13.838085 | BH16: =BG16+(BG16*'1.Premissas Receitas'!$B$19) -> 14.253228 | BI16: =BH16+(BH16*'1.Premissas Receitas'!$B$19) -> 14.680824 | BJ16: =BI16+(BI16*'1.Premissas Receitas'!$B$19) -> 15.121249 | BK16: =BJ16+(BJ16*'1.Premissas Receitas'!$B$19) -> 15.574887 | ... BN16: =BM16+(BM16*'1.Premissas Receitas'!$B$19) -> 17.019099 | BP16: =SUM(G16:R16) -> 18.922706 | BQ16: =SUM(T16:AD16) -> 34.086928 | BR16: =SUM(AE16:AP16) -> 65.989308 | BS16: =SUM(AQ16:BB16) -> 109.61356 | BT16: =SUM(BC16:BN16) -> 174.49043
C17: ='1.Premissas Receitas'!A42 -> # de clientes B2B Manutenção | G17: ='1.Premissas Receitas'!G42 -> 0 | H17: =G17+(G17*'1.Premissas Receitas'!$B$19) -> 0 | I17: =H17+(H17*'1.Premissas Receitas'!$B$19) -> 0 | J17: =I17+(I17*'1.Premissas Receitas'!$B$19) -> 0 | K17: =J17+(J17*'1.Premissas Receitas'!$B$19) -> 0 | L17: =K17+(K17*'1.Premissas Receitas'!$B$19) -> 0 | M17: =L17+(L17*'1.Premissas Receitas'!$B$19) -> 0 | N17: =M17+(M17*'1.Premissas Receitas'!$B$19) -> 0 | O17: =N17+(N17*'1.Premissas Receitas'!$B$19) -> 0 | ... R17: =Q17+(Q17*'1.Premissas Receitas'!$B$19) -> 0 | S17: =R17+(R17*'1.Premissas Receitas'!$G$16) -> 0 | T17: =S17+(S17*'1.Premissas Receitas'!$B$19) -> 0 | U17: =T17+(T17*'1.Premissas Receitas'!$B$19) -> 0 | V17: =U17+(U17*'1.Premissas Receitas'!$B$19) -> 0 | W17: =V17+(V17*'1.Premissas Receitas'!$B$19) -> 0 | X17: =W17+(W17*'1.Premissas Receitas'!$B$19) -> 0 | Y17: =X17+(X17*'1.Premissas Receitas'!$B$19) -> 0 | Z17: =Y17+(Y17*'1.Premissas Receitas'!$B$19) -> 0 | AA17: =Z17+(Z17*'1.Premissas Receitas'!$B$19) -> 0 | ... AD17: =AC17+(AC17*'1.Premissas Receitas'!$B$19) -> 0 | AE17: =AD17+(AD17*'1.Premissas Receitas'!$G$17) -> 0 | AF17: =AE17+(AE17*'1.Premissas Receitas'!$B$19) -> 0 | AG17: =AF17+(AF17*'1.Premissas Receitas'!$B$19) -> 0 | AH17: =AG17+(AG17*'1.Premissas Receitas'!$B$19) -> 0 | AI17: =AH17+(AH17*'1.Premissas Receitas'!$B$19) -> 0 | AJ17: =AI17+(AI17*'1.Premissas Receitas'!$B$19) -> 0 | AK17: =AJ17+(AJ17*'1.Premissas Receitas'!$B$19) -> 0 | AL17: =AK17+(AK17*'1.Premissas Receitas'!$B$19) -> 0 | AM17: =AL17+(AL17*'1.Premissas Receitas'!$B$19) -> 0 | ... AP17: =AO17+(AO17*'1.Premissas Receitas'!$B$19) -> 0 | AQ17: =AP17+(AP17*'1.Premissas Receitas'!$G$18) -> 0 | AR17: =AQ17+(AQ17*'1.Premissas Receitas'!$B$19) -> 0 | AS17: =AR17+(AR17*'1.Premissas Receitas'!$B$19) -> 0 | AT17: =AS17+(AS17*'1.Premissas Receitas'!$B$19) -> 0 | AU17: =AT17+(AT17*'1.Premissas Receitas'!$B$19) -> 0 | AV17: =AU17+(AU17*'1.Premissas Receitas'!$B$19) -> 0 | AW17: =AV17+(AV17*'1.Premissas Receitas'!$B$19) -> 0 | AX17: =AW17+(AW17*'1.Premissas Receitas'!$B$19) -> 0 | AY17: =AX17+(AX17*'1.Premissas Receitas'!$B$19) -> 0 | ... BB17: =BA17+(BA17*'1.Premissas Receitas'!$B$19) -> 0 | BC17: =BB17+(BB17*'1.Premissas Receitas'!$G$19) -> 0 | BD17: =BC17+(BC17*'1.Premissas Receitas'!$B$19) -> 0 | BE17: =BD17+(BD17*'1.Premissas Receitas'!$B$19) -> 0 | BF17: =BE17+(BE17*'1.Premissas Receitas'!$B$19) -> 0 | BG17: =BF17+(BF17*'1.Premissas Receitas'!$B$19) -> 0 | BH17: =BG17+(BG17*'1.Premissas Receitas'!$B$19) -> 0 | BI17: =BH17+(BH17*'1.Premissas Receitas'!$B$19) -> 0 | BJ17: =BI17+(BI17*'1.Premissas Receitas'!$B$19) -> 0 | BK17: =BJ17+(BJ17*'1.Premissas Receitas'!$B$19) -> 0 | ... BN17: =BM17+(BM17*'1.Premissas Receitas'!$B$19) -> 0 | BP17: =SUM(G17:R17) -> 0 | BQ17: =SUM(T17:AD17) -> 0 | BR17: =SUM(AE17:AP17) -> 0 | BS17: =SUM(AQ17:BB17) -> 0 | BT17: =SUM(BC17:BN17) -> 0
C18: ='1.Premissas Receitas'!A48 -> # de clientes Conteudo/ Paywall 1 | G18: ='1.Premissas Receitas'!G48 -> 0 | H18: =G18+(G18*'1.Premissas Receitas'!$B$19) -> 0 | I18: =H18+(H18*'1.Premissas Receitas'!$B$19) -> 0 | J18: =I18+(I18*'1.Premissas Receitas'!$B$19) -> 0 | K18: =J18+(J18*'1.Premissas Receitas'!$B$19) -> 0 | L18: =K18+(K18*'1.Premissas Receitas'!$B$19) -> 0 | M18: =L18+(L18*'1.Premissas Receitas'!$B$19) -> 0 | N18: =M18+(M18*'1.Premissas Receitas'!$B$19) -> 0 | O18: =N18+(N18*'1.Premissas Receitas'!$B$19) -> 0 | ... R18: =Q18+(Q18*'1.Premissas Receitas'!$B$19) -> 0 | S18: =R18+(R18*'1.Premissas Receitas'!$G$16) -> 0 | T18: =S18+(S18*'1.Premissas Receitas'!$B$19) -> 0 | U18: =T18+(T18*'1.Premissas Receitas'!$B$19) -> 0 | V18: =U18+(U18*'1.Premissas Receitas'!$B$19) -> 0 | W18: =V18+(V18*'1.Premissas Receitas'!$B$19) -> 0 | X18: =W18+(W18*'1.Premissas Receitas'!$B$19) -> 0 | Y18: =X18+(X18*'1.Premissas Receitas'!$B$19) -> 0 | Z18: =Y18+(Y18*'1.Premissas Receitas'!$B$19) -> 0 | AA18: =Z18+(Z18*'1.Premissas Receitas'!$B$19) -> 0 | ... AD18: =AC18+(AC18*'1.Premissas Receitas'!$B$19) -> 0 | AE18: =AD18+(AD18*'1.Premissas Receitas'!$G$17) -> 0 | AF18: =AE18+(AE18*'1.Premissas Receitas'!$B$19) -> 0 | AG18: =AF18+(AF18*'1.Premissas Receitas'!$B$19) -> 0 | AH18: =AG18+(AG18*'1.Premissas Receitas'!$B$19) -> 0 | AI18: =AH18+(AH18*'1.Premissas Receitas'!$B$19) -> 0 | AJ18: =AI18+(AI18*'1.Premissas Receitas'!$B$19) -> 0 | AK18: =AJ18+(AJ18*'1.Premissas Receitas'!$B$19) -> 0 | AL18: =AK18+(AK18*'1.Premissas Receitas'!$B$19) -> 0 | AM18: =AL18+(AL18*'1.Premissas Receitas'!$B$19) -> 0 | ... AP18: =AO18+(AO18*'1.Premissas Receitas'!$B$19) -> 0 | AQ18: =AP18+(AP18*'1.Premissas Receitas'!$G$18) -> 0 | AR18: =AQ18+(AQ18*'1.Premissas Receitas'!$B$19) -> 0 | AS18: =AR18+(AR18*'1.Premissas Receitas'!$B$19) -> 0 | AT18: =AS18+(AS18*'1.Premissas Receitas'!$B$19) -> 0 | AU18: =AT18+(AT18*'1.Premissas Receitas'!$B$19) -> 0 | AV18: =AU18+(AU18*'1.Premissas Receitas'!$B$19) -> 0 | AW18: =AV18+(AV18*'1.Premissas Receitas'!$B$19) -> 0 | AX18: =AW18+(AW18*'1.Premissas Receitas'!$B$19) -> 0 | AY18: =AX18+(AX18*'1.Premissas Receitas'!$B$19) -> 0 | ... BB18: =BA18+(BA18*'1.Premissas Receitas'!$B$19) -> 0 | BC18: =BB18+(BB18*'1.Premissas Receitas'!$G$19) -> 0 | BD18: =BC18+(BC18*'1.Premissas Receitas'!$B$19) -> 0 | BE18: =BD18+(BD18*'1.Premissas Receitas'!$B$19) -> 0 | BF18: =BE18+(BE18*'1.Premissas Receitas'!$B$19) -> 0 | BG18: =BF18+(BF18*'1.Premissas Receitas'!$B$19) -> 0 | BH18: =BG18+(BG18*'1.Premissas Receitas'!$B$19) -> 0 | BI18: =BH18+(BH18*'1.Premissas Receitas'!$B$19) -> 0 | BJ18: =BI18+(BI18*'1.Premissas Receitas'!$B$19) -> 0 | BK18: =BJ18+(BJ18*'1.Premissas Receitas'!$B$19) -> 0 | ... BN18: =BM18+(BM18*'1.Premissas Receitas'!$B$19) -> 0 | BP18: =SUM(G18:R18) -> 0 | BQ18: =SUM(T18:AD18) -> 0 | BR18: =SUM(AE18:AP18) -> 0 | BS18: =SUM(AQ18:BB18) -> 0 | BT18: =SUM(BC18:BN18) -> 0
C19: ='1.Premissas Receitas'!A49 -> # de clientes Conteudo/ Paywall 2 | G19: ='1.Premissas Receitas'!G49 -> 0 | H19: =G19+(G19*'1.Premissas Receitas'!$B$19) -> 0 | I19: =H19+(H19*'1.Premissas Receitas'!$B$19) -> 0 | J19: =I19+(I19*'1.Premissas Receitas'!$B$19) -> 0 | K19: =J19+(J19*'1.Premissas Receitas'!$B$19) -> 0 | L19: =K19+(K19*'1.Premissas Receitas'!$B$19) -> 0 | M19: =L19+(L19*'1.Premissas Receitas'!$B$19) -> 0 | N19: =M19+(M19*'1.Premissas Receitas'!$B$19) -> 0 | O19: =N19+(N19*'1.Premissas Receitas'!$B$19) -> 0 | ... R19: =Q19+(Q19*'1.Premissas Receitas'!$B$19) -> 0 | S19: =R19+(R19*'1.Premissas Receitas'!$G$16) -> 0 | T19: =S19+(S19*'1.Premissas Receitas'!$B$19) -> 0 | U19: =T19+(T19*'1.Premissas Receitas'!$B$19) -> 0 | V19: =U19+(U19*'1.Premissas Receitas'!$B$19) -> 0 | W19: =V19+(V19*'1.Premissas Receitas'!$B$19) -> 0 | X19: =W19+(W19*'1.Premissas Receitas'!$B$19) -> 0 | Y19: =X19+(X19*'1.Premissas Receitas'!$B$19) -> 0 | Z19: =Y19+(Y19*'1.Premissas Receitas'!$B$19) -> 0 | AA19: =Z19+(Z19*'1.Premissas Receitas'!$B$19) -> 0 | ... AD19: =AC19+(AC19*'1.Premissas Receitas'!$B$19) -> 0 | AE19: =AD19+(AD19*'1.Premissas Receitas'!$G$17) -> 0 | AF19: =AE19+(AE19*'1.Premissas Receitas'!$B$19) -> 0 | AG19: =AF19+(AF19*'1.Premissas Receitas'!$B$19) -> 0 | AH19: =AG19+(AG19*'1.Premissas Receitas'!$B$19) -> 0 | AI19: =AH19+(AH19*'1.Premissas Receitas'!$B$19) -> 0 | AJ19: =AI19+(AI19*'1.Premissas Receitas'!$B$19) -> 0 | AK19: =AJ19+(AJ19*'1.Premissas Receitas'!$B$19) -> 0 | AL19: =AK19+(AK19*'1.Premissas Receitas'!$B$19) -> 0 | AM19: =AL19+(AL19*'1.Premissas Receitas'!$B$19) -> 0 | ... AP19: =AO19+(AO19*'1.Premissas Receitas'!$B$19) -> 0 | AQ19: =AP19+(AP19*'1.Premissas Receitas'!$G$18) -> 0 | AR19: =AQ19+(AQ19*'1.Premissas Receitas'!$B$19) -> 0 | AS19: =AR19+(AR19*'1.Premissas Receitas'!$B$19) -> 0 | AT19: =AS19+(AS19*'1.Premissas Receitas'!$B$19) -> 0 | AU19: =AT19+(AT19*'1.Premissas Receitas'!$B$19) -> 0 | AV19: =AU19+(AU19*'1.Premissas Receitas'!$B$19) -> 0 | AW19: =AV19+(AV19*'1.Premissas Receitas'!$B$19) -> 0 | AX19: =AW19+(AW19*'1.Premissas Receitas'!$B$19) -> 0 | AY19: =AX19+(AX19*'1.Premissas Receitas'!$B$19) -> 0 | ... BB19: =BA19+(BA19*'1.Premissas Receitas'!$B$19) -> 0 | BC19: =BB19+(BB19*'1.Premissas Receitas'!$G$19) -> 0 | BD19: =BC19+(BC19*'1.Premissas Receitas'!$B$19) -> 0 | BE19: =BD19+(BD19*'1.Premissas Receitas'!$B$19) -> 0 | BF19: =BE19+(BE19*'1.Premissas Receitas'!$B$19) -> 0 | BG19: =BF19+(BF19*'1.Premissas Receitas'!$B$19) -> 0 | BH19: =BG19+(BG19*'1.Premissas Receitas'!$B$19) -> 0 | BI19: =BH19+(BH19*'1.Premissas Receitas'!$B$19) -> 0 | BJ19: =BI19+(BI19*'1.Premissas Receitas'!$B$19) -> 0 | BK19: =BJ19+(BJ19*'1.Premissas Receitas'!$B$19) -> 0 | ... BN19: =BM19+(BM19*'1.Premissas Receitas'!$B$19) -> 0 | BP19: =SUM(G19:R19) -> 0 | BQ19: =SUM(T19:AD19) -> 0 | BR19: =SUM(AE19:AP19) -> 0 | BS19: =SUM(AQ19:BB19) -> 0 | BT19: =SUM(BC19:BN19) -> 0
C20: ='1.Premissas Receitas'!A50 -> # de clientes Conteudo/ Paywall 3 | G20: ='1.Premissas Receitas'!G50 -> 0 | H20: =G20+(G20*'1.Premissas Receitas'!$B$19) -> 0 | I20: =H20+(H20*'1.Premissas Receitas'!$B$19) -> 0 | J20: =I20+(I20*'1.Premissas Receitas'!$B$19) -> 0 | K20: =J20+(J20*'1.Premissas Receitas'!$B$19) -> 0 | L20: =K20+(K20*'1.Premissas Receitas'!$B$19) -> 0 | M20: =L20+(L20*'1.Premissas Receitas'!$B$19) -> 0 | N20: =M20+(M20*'1.Premissas Receitas'!$B$19) -> 0 | O20: =N20+(N20*'1.Premissas Receitas'!$B$19) -> 0 | ... R20: =Q20+(Q20*'1.Premissas Receitas'!$B$19) -> 0 | S20: =R20+(R20*'1.Premissas Receitas'!$G$16) -> 0 | T20: =S20+(S20*'1.Premissas Receitas'!$B$19) -> 0 | U20: =T20+(T20*'1.Premissas Receitas'!$B$19) -> 0 | V20: =U20+(U20*'1.Premissas Receitas'!$B$19) -> 0 | W20: =V20+(V20*'1.Premissas Receitas'!$B$19) -> 0 | X20: =W20+(W20*'1.Premissas Receitas'!$B$19) -> 0 | Y20: =X20+(X20*'1.Premissas Receitas'!$B$19) -> 0 | Z20: =Y20+(Y20*'1.Premissas Receitas'!$B$19) -> 0 | AA20: =Z20+(Z20*'1.Premissas Receitas'!$B$19) -> 0 | ... AD20: =AC20+(AC20*'1.Premissas Receitas'!$B$19) -> 0 | AE20: =AD20+(AD20*'1.Premissas Receitas'!$G$17) -> 0 | AF20: =AE20+(AE20*'1.Premissas Receitas'!$B$19) -> 0 | AG20: =AF20+(AF20*'1.Premissas Receitas'!$B$19) -> 0 | AH20: =AG20+(AG20*'1.Premissas Receitas'!$B$19) -> 0 | AI20: =AH20+(AH20*'1.Premissas Receitas'!$B$19) -> 0 | AJ20: =AI20+(AI20*'1.Premissas Receitas'!$B$19) -> 0 | AK20: =AJ20+(AJ20*'1.Premissas Receitas'!$B$19) -> 0 | AL20: =AK20+(AK20*'1.Premissas Receitas'!$B$19) -> 0 | AM20: =AL20+(AL20*'1.Premissas Receitas'!$B$19) -> 0 | ... AP20: =AO20+(AO20*'1.Premissas Receitas'!$B$19) -> 0 | AQ20: =AP20+(AP20*'1.Premissas Receitas'!$G$18) -> 0 | AR20: =AQ20+(AQ20*'1.Premissas Receitas'!$B$19) -> 0 | AS20: =AR20+(AR20*'1.Premissas Receitas'!$B$19) -> 0 | AT20: =AS20+(AS20*'1.Premissas Receitas'!$B$19) -> 0 | AU20: =AT20+(AT20*'1.Premissas Receitas'!$B$19) -> 0 | AV20: =AU20+(AU20*'1.Premissas Receitas'!$B$19) -> 0 | AW20: =AV20+(AV20*'1.Premissas Receitas'!$B$19) -> 0 | AX20: =AW20+(AW20*'1.Premissas Receitas'!$B$19) -> 0 | AY20: =AX20+(AX20*'1.Premissas Receitas'!$B$19) -> 0 | ... BB20: =BA20+(BA20*'1.Premissas Receitas'!$B$19) -> 0 | BC20: =BB20+(BB20*'1.Premissas Receitas'!$G$19) -> 0 | BD20: =BC20+(BC20*'1.Premissas Receitas'!$B$19) -> 0 | BE20: =BD20+(BD20*'1.Premissas Receitas'!$B$19) -> 0 | BF20: =BE20+(BE20*'1.Premissas Receitas'!$B$19) -> 0 | BG20: =BF20+(BF20*'1.Premissas Receitas'!$B$19) -> 0 | BH20: =BG20+(BG20*'1.Premissas Receitas'!$B$19) -> 0 | BI20: =BH20+(BH20*'1.Premissas Receitas'!$B$19) -> 0 | BJ20: =BI20+(BI20*'1.Premissas Receitas'!$B$19) -> 0 | BK20: =BJ20+(BJ20*'1.Premissas Receitas'!$B$19) -> 0 | ... BN20: =BM20+(BM20*'1.Premissas Receitas'!$B$19) -> 0 | BP20: =SUM(G20:R20) -> 0 | BQ20: =SUM(T20:AD20) -> 0 | BR20: =SUM(AE20:AP20) -> 0 | BS20: =SUM(AQ20:BB20) -> 0 | BT20: =SUM(BC20:BN20) -> 0
C21: ='1.Premissas Receitas'!A56 -> # de clientes publicidade Produto/Serviço 1 | G21: ='1.Premissas Receitas'!G56 -> 0 | H21: =G21+(G21*'1.Premissas Receitas'!$B$19) -> 0 | I21: =H21+(H21*'1.Premissas Receitas'!$B$19) -> 0 | J21: =I21+(I21*'1.Premissas Receitas'!$B$19) -> 0 | K21: =J21+(J21*'1.Premissas Receitas'!$B$19) -> 0 | L21: =K21+(K21*'1.Premissas Receitas'!$B$19) -> 0 | M21: =L21+(L21*'1.Premissas Receitas'!$B$19) -> 0 | N21: =M21+(M21*'1.Premissas Receitas'!$B$19) -> 0 | O21: =N21+(N21*'1.Premissas Receitas'!$B$19) -> 0 | ... R21: =Q21+(Q21*'1.Premissas Receitas'!$B$19) -> 0 | S21: =R21+(R21*'1.Premissas Receitas'!$G$16) -> 0 | T21: =S21+(S21*'1.Premissas Receitas'!$B$19) -> 0 | U21: =T21+(T21*'1.Premissas Receitas'!$B$19) -> 0 | V21: =U21+(U21*'1.Premissas Receitas'!$B$19) -> 0 | W21: =V21+(V21*'1.Premissas Receitas'!$B$19) -> 0 | X21: =W21+(W21*'1.Premissas Receitas'!$B$19) -> 0 | Y21: =X21+(X21*'1.Premissas Receitas'!$B$19) -> 0 | Z21: =Y21+(Y21*'1.Premissas Receitas'!$B$19) -> 0 | AA21: =Z21+(Z21*'1.Premissas Receitas'!$B$19) -> 0 | ... AD21: =AC21+(AC21*'1.Premissas Receitas'!$B$19) -> 0 | AE21: =AD21+(AD21*'1.Premissas Receitas'!$G$17) -> 0 | AF21: =AE21+(AE21*'1.Premissas Receitas'!$B$19) -> 0 | AG21: =AF21+(AF21*'1.Premissas Receitas'!$B$19) -> 0 | AH21: =AG21+(AG21*'1.Premissas Receitas'!$B$19) -> 0 | AI21: =AH21+(AH21*'1.Premissas Receitas'!$B$19) -> 0 | AJ21: =AI21+(AI21*'1.Premissas Receitas'!$B$19) -> 0 | AK21: =AJ21+(AJ21*'1.Premissas Receitas'!$B$19) -> 0 | AL21: =AK21+(AK21*'1.Premissas Receitas'!$B$19) -> 0 | AM21: =AL21+(AL21*'1.Premissas Receitas'!$B$19) -> 0 | ... AP21: =AO21+(AO21*'1.Premissas Receitas'!$B$19) -> 0 | AQ21: =AP21+(AP21*'1.Premissas Receitas'!$G$18) -> 0 | AR21: =AQ21+(AQ21*'1.Premissas Receitas'!$B$19) -> 0 | AS21: =AR21+(AR21*'1.Premissas Receitas'!$B$19) -> 0 | AT21: =AS21+(AS21*'1.Premissas Receitas'!$B$19) -> 0 | AU21: =AT21+(AT21*'1.Premissas Receitas'!$B$19) -> 0 | AV21: =AU21+(AU21*'1.Premissas Receitas'!$B$19) -> 0 | AW21: =AV21+(AV21*'1.Premissas Receitas'!$B$19) -> 0 | AX21: =AW21+(AW21*'1.Premissas Receitas'!$B$19) -> 0 | AY21: =AX21+(AX21*'1.Premissas Receitas'!$B$19) -> 0 | ... BB21: =BA21+(BA21*'1.Premissas Receitas'!$B$19) -> 0 | BC21: =BB21+(BB21*'1.Premissas Receitas'!$G$19) -> 0 | BD21: =BC21+(BC21*'1.Premissas Receitas'!$B$19) -> 0 | BE21: =BD21+(BD21*'1.Premissas Receitas'!$B$19) -> 0 | BF21: =BE21+(BE21*'1.Premissas Receitas'!$B$19) -> 0 | BG21: =BF21+(BF21*'1.Premissas Receitas'!$B$19) -> 0 | BH21: =BG21+(BG21*'1.Premissas Receitas'!$B$19) -> 0 | BI21: =BH21+(BH21*'1.Premissas Receitas'!$B$19) -> 0 | BJ21: =BI21+(BI21*'1.Premissas Receitas'!$B$19) -> 0 | BK21: =BJ21+(BJ21*'1.Premissas Receitas'!$B$19) -> 0 | ... BN21: =BM21+(BM21*'1.Premissas Receitas'!$B$19) -> 0 | BP21: =SUM(G21:R21) -> 0 | BQ21: =SUM(T21:AD21) -> 0 | BR21: =SUM(AE21:AP21) -> 0 | BS21: =SUM(AQ21:BB21) -> 0 | BT21: =SUM(BC21:BN21) -> 0
C22: ='1.Premissas Receitas'!A57 -> # de clientes publicidade Produto/Serviço 2 | G22: ='1.Premissas Receitas'!G57 -> 0 | H22: =G22+(G22*'1.Premissas Receitas'!$B$19) -> 0 | I22: =H22+(H22*'1.Premissas Receitas'!$B$19) -> 0 | J22: =I22+(I22*'1.Premissas Receitas'!$B$19) -> 0 | K22: =J22+(J22*'1.Premissas Receitas'!$B$19) -> 0 | L22: =K22+(K22*'1.Premissas Receitas'!$B$19) -> 0 | M22: =L22+(L22*'1.Premissas Receitas'!$B$19) -> 0 | N22: =M22+(M22*'1.Premissas Receitas'!$B$19) -> 0 | O22: =N22+(N22*'1.Premissas Receitas'!$B$19) -> 0 | ... R22: =Q22+(Q22*'1.Premissas Receitas'!$B$19) -> 0 | S22: =R22+(R22*'1.Premissas Receitas'!$G$16) -> 0 | T22: =S22+(S22*'1.Premissas Receitas'!$B$19) -> 0 | U22: =T22+(T22*'1.Premissas Receitas'!$B$19) -> 0 | V22: =U22+(U22*'1.Premissas Receitas'!$B$19) -> 0 | W22: =V22+(V22*'1.Premissas Receitas'!$B$19) -> 0 | X22: =W22+(W22*'1.Premissas Receitas'!$B$19) -> 0 | Y22: =X22+(X22*'1.Premissas Receitas'!$B$19) -> 0 | Z22: =Y22+(Y22*'1.Premissas Receitas'!$B$19) -> 0 | AA22: =Z22+(Z22*'1.Premissas Receitas'!$B$19) -> 0 | ... AD22: =AC22+(AC22*'1.Premissas Receitas'!$B$19) -> 0 | AE22: =AD22+(AD22*'1.Premissas Receitas'!$G$17) -> 0 | AF22: =AE22+(AE22*'1.Premissas Receitas'!$B$19) -> 0 | AG22: =AF22+(AF22*'1.Premissas Receitas'!$B$19) -> 0 | AH22: =AG22+(AG22*'1.Premissas Receitas'!$B$19) -> 0 | AI22: =AH22+(AH22*'1.Premissas Receitas'!$B$19) -> 0 | AJ22: =AI22+(AI22*'1.Premissas Receitas'!$B$19) -> 0 | AK22: =AJ22+(AJ22*'1.Premissas Receitas'!$B$19) -> 0 | AL22: =AK22+(AK22*'1.Premissas Receitas'!$B$19) -> 0 | AM22: =AL22+(AL22*'1.Premissas Receitas'!$B$19) -> 0 | ... AP22: =AO22+(AO22*'1.Premissas Receitas'!$B$19) -> 0 | AQ22: =AP22+(AP22*'1.Premissas Receitas'!$G$18) -> 0 | AR22: =AQ22+(AQ22*'1.Premissas Receitas'!$B$19) -> 0 | AS22: =AR22+(AR22*'1.Premissas Receitas'!$B$19) -> 0 | AT22: =AS22+(AS22*'1.Premissas Receitas'!$B$19) -> 0 | AU22: =AT22+(AT22*'1.Premissas Receitas'!$B$19) -> 0 | AV22: =AU22+(AU22*'1.Premissas Receitas'!$B$19) -> 0 | AW22: =AV22+(AV22*'1.Premissas Receitas'!$B$19) -> 0 | AX22: =AW22+(AW22*'1.Premissas Receitas'!$B$19) -> 0 | AY22: =AX22+(AX22*'1.Premissas Receitas'!$B$19) -> 0 | ... BB22: =BA22+(BA22*'1.Premissas Receitas'!$B$19) -> 0 | BC22: =BB22+(BB22*'1.Premissas Receitas'!$G$19) -> 0 | BD22: =BC22+(BC22*'1.Premissas Receitas'!$B$19) -> 0 | BE22: =BD22+(BD22*'1.Premissas Receitas'!$B$19) -> 0 | BF22: =BE22+(BE22*'1.Premissas Receitas'!$B$19) -> 0 | BG22: =BF22+(BF22*'1.Premissas Receitas'!$B$19) -> 0 | BH22: =BG22+(BG22*'1.Premissas Receitas'!$B$19) -> 0 | BI22: =BH22+(BH22*'1.Premissas Receitas'!$B$19) -> 0 | BJ22: =BI22+(BI22*'1.Premissas Receitas'!$B$19) -> 0 | BK22: =BJ22+(BJ22*'1.Premissas Receitas'!$B$19) -> 0 | ... BN22: =BM22+(BM22*'1.Premissas Receitas'!$B$19) -> 0 | BP22: =SUM(G22:R22) -> 0 | BQ22: =SUM(T22:AD22) -> 0 | BR22: =SUM(AE22:AP22) -> 0 | BS22: =SUM(AQ22:BB22) -> 0 | BT22: =SUM(BC22:BN22) -> 0
C23: ='1.Premissas Receitas'!A58 -> # de clientes publicidade Produto/Serviço 3 | G23: ='1.Premissas Receitas'!G58 -> 0 | H23: =G23+(G23*'1.Premissas Receitas'!$B$19) -> 0 | I23: =H23+(H23*'1.Premissas Receitas'!$B$19) -> 0 | J23: =I23+(I23*'1.Premissas Receitas'!$B$19) -> 0 | K23: =J23+(J23*'1.Premissas Receitas'!$B$19) -> 0 | L23: =K23+(K23*'1.Premissas Receitas'!$B$19) -> 0 | M23: =L23+(L23*'1.Premissas Receitas'!$B$19) -> 0 | N23: =M23+(M23*'1.Premissas Receitas'!$B$19) -> 0 | O23: =N23+(N23*'1.Premissas Receitas'!$B$19) -> 0 | ... R23: =Q23+(Q23*'1.Premissas Receitas'!$B$19) -> 0 | S23: =R23+(R23*'1.Premissas Receitas'!$G$16) -> 0 | T23: =S23+(S23*'1.Premissas Receitas'!$B$19) -> 0 | U23: =T23+(T23*'1.Premissas Receitas'!$B$19) -> 0 | V23: =U23+(U23*'1.Premissas Receitas'!$B$19) -> 0 | W23: =V23+(V23*'1.Premissas Receitas'!$B$19) -> 0 | X23: =W23+(W23*'1.Premissas Receitas'!$B$19) -> 0 | Y23: =X23+(X23*'1.Premissas Receitas'!$B$19) -> 0 | Z23: =Y23+(Y23*'1.Premissas Receitas'!$B$19) -> 0 | AA23: =Z23+(Z23*'1.Premissas Receitas'!$B$19) -> 0 | ... AD23: =AC23+(AC23*'1.Premissas Receitas'!$B$19) -> 0 | AE23: =AD23+(AD23*'1.Premissas Receitas'!$G$17) -> 0 | AF23: =AE23+(AE23*'1.Premissas Receitas'!$B$19) -> 0 | AG23: =AF23+(AF23*'1.Premissas Receitas'!$B$19) -> 0 | AH23: =AG23+(AG23*'1.Premissas Receitas'!$B$19) -> 0 | AI23: =AH23+(AH23*'1.Premissas Receitas'!$B$19) -> 0 | AJ23: =AI23+(AI23*'1.Premissas Receitas'!$B$19) -> 0 | AK23: =AJ23+(AJ23*'1.Premissas Receitas'!$B$19) -> 0 | AL23: =AK23+(AK23*'1.Premissas Receitas'!$B$19) -> 0 | AM23: =AL23+(AL23*'1.Premissas Receitas'!$B$19) -> 0 | ... AP23: =AO23+(AO23*'1.Premissas Receitas'!$B$19) -> 0 | AQ23: =AP23+(AP23*'1.Premissas Receitas'!$G$18) -> 0 | AR23: =AQ23+(AQ23*'1.Premissas Receitas'!$B$19) -> 0 | AS23: =AR23+(AR23*'1.Premissas Receitas'!$B$19) -> 0 | AT23: =AS23+(AS23*'1.Premissas Receitas'!$B$19) -> 0 | AU23: =AT23+(AT23*'1.Premissas Receitas'!$B$19) -> 0 | AV23: =AU23+(AU23*'1.Premissas Receitas'!$B$19) -> 0 | AW23: =AV23+(AV23*'1.Premissas Receitas'!$B$19) -> 0 | AX23: =AW23+(AW23*'1.Premissas Receitas'!$B$19) -> 0 | AY23: =AX23+(AX23*'1.Premissas Receitas'!$B$19) -> 0 | ... BB23: =BA23+(BA23*'1.Premissas Receitas'!$B$19) -> 0 | BC23: =BB23+(BB23*'1.Premissas Receitas'!$G$19) -> 0 | BD23: =BC23+(BC23*'1.Premissas Receitas'!$B$19) -> 0 | BE23: =BD23+(BD23*'1.Premissas Receitas'!$B$19) -> 0 | BF23: =BE23+(BE23*'1.Premissas Receitas'!$B$19) -> 0 | BG23: =BF23+(BF23*'1.Premissas Receitas'!$B$19) -> 0 | BH23: =BG23+(BG23*'1.Premissas Receitas'!$B$19) -> 0 | BI23: =BH23+(BH23*'1.Premissas Receitas'!$B$19) -> 0 | BJ23: =BI23+(BI23*'1.Premissas Receitas'!$B$19) -> 0 | BK23: =BJ23+(BJ23*'1.Premissas Receitas'!$B$19) -> 0 | ... BN23: =BM23+(BM23*'1.Premissas Receitas'!$B$19) -> 0 | BP23: =SUM(G23:R23) -> 0 | BQ23: =SUM(T23:AD23) -> 0 | BR23: =SUM(AE23:AP23) -> 0 | BS23: =SUM(AQ23:BB23) -> 0 | BT23: =SUM(BC23:BN23) -> 0
C24: ='1.Premissas Receitas'!A63 -> # Pay-per-use Produto/Serviço 1 | G24: ='1.Premissas Receitas'!G63 -> 0 | H24: =G24+(G24*'1.Premissas Receitas'!$B$19) -> 0 | I24: =H24+(H24*'1.Premissas Receitas'!$B$19) -> 0 | J24: =I24+(I24*'1.Premissas Receitas'!$B$19) -> 0 | K24: =J24+(J24*'1.Premissas Receitas'!$B$19) -> 0 | L24: =K24+(K24*'1.Premissas Receitas'!$B$19) -> 0 | M24: =L24+(L24*'1.Premissas Receitas'!$B$19) -> 0 | N24: =M24+(M24*'1.Premissas Receitas'!$B$19) -> 0 | O24: =N24+(N24*'1.Premissas Receitas'!$B$19) -> 0 | ... R24: =Q24+(Q24*'1.Premissas Receitas'!$B$19) -> 0 | S24: =R24+(R24*'1.Premissas Receitas'!$G$16) -> 0 | T24: =S24+(S24*'1.Premissas Receitas'!$B$19) -> 0 | U24: =T24+(T24*'1.Premissas Receitas'!$B$19) -> 0 | V24: =U24+(U24*'1.Premissas Receitas'!$B$19) -> 0 | W24: =V24+(V24*'1.Premissas Receitas'!$B$19) -> 0 | X24: =W24+(W24*'1.Premissas Receitas'!$B$19) -> 0 | Y24: =X24+(X24*'1.Premissas Receitas'!$B$19) -> 0 | Z24: =Y24+(Y24*'1.Premissas Receitas'!$B$19) -> 0 | AA24: =Z24+(Z24*'1.Premissas Receitas'!$B$19) -> 0 | ... AD24: =AC24+(AC24*'1.Premissas Receitas'!$B$19) -> 0 | AE24: =AD24+(AD24*'1.Premissas Receitas'!$G$17) -> 0 | AF24: =AE24+(AE24*'1.Premissas Receitas'!$B$19) -> 0 | AG24: =AF24+(AF24*'1.Premissas Receitas'!$B$19) -> 0 | AH24: =AG24+(AG24*'1.Premissas Receitas'!$B$19) -> 0 | AI24: =AH24+(AH24*'1.Premissas Receitas'!$B$19) -> 0 | AJ24: =AI24+(AI24*'1.Premissas Receitas'!$B$19) -> 0 | AK24: =AJ24+(AJ24*'1.Premissas Receitas'!$B$19) -> 0 | AL24: =AK24+(AK24*'1.Premissas Receitas'!$B$19) -> 0 | AM24: =AL24+(AL24*'1.Premissas Receitas'!$B$19) -> 0 | ... AP24: =AO24+(AO24*'1.Premissas Receitas'!$B$19) -> 0 | AQ24: =AP24+(AP24*'1.Premissas Receitas'!$G$18) -> 0 | AR24: =AQ24+(AQ24*'1.Premissas Receitas'!$B$19) -> 0 | AS24: =AR24+(AR24*'1.Premissas Receitas'!$B$19) -> 0 | AT24: =AS24+(AS24*'1.Premissas Receitas'!$B$19) -> 0 | AU24: =AT24+(AT24*'1.Premissas Receitas'!$B$19) -> 0 | AV24: =AU24+(AU24*'1.Premissas Receitas'!$B$19) -> 0 | AW24: =AV24+(AV24*'1.Premissas Receitas'!$B$19) -> 0 | AX24: =AW24+(AW24*'1.Premissas Receitas'!$B$19) -> 0 | AY24: =AX24+(AX24*'1.Premissas Receitas'!$B$19) -> 0 | ... BB24: =BA24+(BA24*'1.Premissas Receitas'!$B$19) -> 0 | BC24: =BB24+(BB24*'1.Premissas Receitas'!$G$19) -> 0 | BD24: =BC24+(BC24*'1.Premissas Receitas'!$B$19) -> 0 | BE24: =BD24+(BD24*'1.Premissas Receitas'!$B$19) -> 0 | BF24: =BE24+(BE24*'1.Premissas Receitas'!$B$19) -> 0 | BG24: =BF24+(BF24*'1.Premissas Receitas'!$B$19) -> 0 | BH24: =BG24+(BG24*'1.Premissas Receitas'!$B$19) -> 0 | BI24: =BH24+(BH24*'1.Premissas Receitas'!$B$19) -> 0 | BJ24: =BI24+(BI24*'1.Premissas Receitas'!$B$19) -> 0 | BK24: =BJ24+(BJ24*'1.Premissas Receitas'!$B$19) -> 0 | ... BN24: =BM24+(BM24*'1.Premissas Receitas'!$B$19) -> 0 | BP24: =SUM(G24:R24) -> 0 | BQ24: =SUM(T24:AD24) -> 0 | BR24: =SUM(AE24:AP24) -> 0 | BS24: =SUM(AQ24:BB24) -> 0 | BT24: =SUM(BC24:BN24) -> 0
